<?xml version="1.0"?>
<!-- created with Phobos 0.7 -->
  <robot name="ur5">

    <link name="base_link">
      <inertial>
        <origin xyz="0 0 0" rpy="0 0 0"/>
        <mass value="4.0"/>
        <inertia ixx="0.00443" ixy="0" ixz="0" iyy="0.00443" iyz="0" izz="0.0072"/>
      </inertial>
      <visual name="visual_0_base_link">
        <origin xyz="0 0 0" rpy="0 0 0"/>
        <geometry>
          <mesh filename="meshes/stl/Base.009.stl" scale="1.0 1.0 1.0"/>
        </geometry>
        <material name="LightGrey"/>
      </visual>
      <collision name="collision_0_base_link">
        <origin xyz="0 -0.01832 0.009" rpy="0 0 0"/>
        <geometry>
          <box size="0.14673 0.18337 0.024"/>
        </geometry>
      </collision>
    </link>

    <link name="ee_link">
    </link>

    <link name="forearm_link"><!--  -->
      <inertial>
        <origin xyz="0 0 0" rpy="0 0 0"/>
        <mass value="2.275"/>
        <inertia ixx="0.04944" ixy="0" ixz="0" iyy="0.04944" iyz="0" izz="0.0041"/>
      </inertial>
      <visual name="visual_0_forearm_link">
        <origin xyz="0 0 0" rpy="0 0 0"/>
        <geometry>
          <mesh filename="meshes/stl/Forearm.009.stl" scale="1.0 1.0 1.0"/>
        </geometry>
        <material name="LightGrey"/>
      </visual>
      <collision name="collision_0_forearm_link">
        <origin xyz="0 -0.00135 0.18659" rpy="0 0 0"/>
        <geometry>
          <box size="0.116 0.1117 0.48918"/>
        </geometry>
      </collision>
    </link>

    <link name="fts_robotside">
      <inertial>
        <origin xyz="0 0 0" rpy="0 0 0"/>
        <mass value="0.65"/>
        <inertia ixx="0.001" ixy="0" ixz="0" iyy="0.001" iyz="0" izz="0.00117"/>
      </inertial>
      <visual name="visual_cable_mesh_2_001">
        <origin xyz="0 0 0" rpy="1.5708 0 -1.5708"/>
        <geometry>
          <mesh filename="meshes/stl/mesh 2.000.stl" scale="1.0 1.0 1.0"/>
        </geometry>
        <material name="black"/>
      </visual>
      <visual name="visual_mesh_1_001">
        <origin xyz="0 0 0" rpy="1.5708 0 -1.5708"/>
        <geometry>
          <mesh filename="meshes/stl/mesh 1.001.stl" scale="1.0 1.0 1.0"/>
        </geometry>
        <material name="black"/>
      </visual>
      <collision name="collision_cable_mesh_2_001">
        <origin xyz="-0.06239 0 0.008" rpy="1.5708 0 -1.5708"/>
        <geometry>
          <cylinder radius="0.004" length="0.05"/>
        </geometry>
      </collision>
      <collision name="collision_mesh_1_001">
        <origin xyz="0 0 0.01875" rpy="-3.14159 0 -1.5708"/>
        <geometry>
          <cylinder radius="0.0375" length="0.03079"/>
        </geometry>
      </collision>
    </link>

    <link name="fts_toolside">
    </link>

    <link name="left_inner_finger"><!--  -->
      <inertial>
        <origin xyz="-0.0002 0.01926 -0.00896" rpy="0 0 0"/>
        <mass value="0.01"/>
        <inertia ixx="0.001" ixy="0" ixz="0" iyy="0.001" iyz="0" izz="0.001"/>
      </inertial>
      <visual name="visual_0_left_inner_finger">
        <origin xyz="0 0 0" rpy="0 0 0"/>
        <geometry>
          <mesh filename="meshes/stl/Robotiq Arg2F 140 Inner Finger.002.stl" scale="1.0 1.0 1.0"/>
        </geometry>
        <material name="LightGrey"/>
      </visual>
      <!-- <collision name="collision_0_left_inner_finger">         -->
      <!--   <origin xyz="-0.0002 0.01926 -0.00896" rpy="0 0 0"/>   -->
      <!--   <geometry>                                             -->
      <!--     <box size="0.015 0.0505 0.02988"/>                   -->
      <!--   </geometry>                                            -->
      <!-- </collision>                                             -->
    </link>

	  <link name="left_extension">

      <visual name="visual0_left_extension">
        <origin xyz="0 0.04 -0.027" rpy="1.57 0 0"/>
        <geometry>
          <box size="0.02 0.005 0.05"/>
        </geometry>
        <material name="LightGrey"/>
      </visual>

      <collision name="collision_0_left_extension">
        <origin xyz="0 0.04 -0.027" rpy="1.57 0 0"/>
        <geometry>
          <box size="0.02 0.005 0.05"/>
        </geometry>
      </collision>

    </link>

    <link name="left_inner_knuckle"><!--  -->
      <inertial>
        <origin xyz="-5e-05 0.04999 -0.00111" rpy="0 0 0"/>
        <mass value="0.027"/>
        <inertia ixx="0.001" ixy="0" ixz="0" iyy="0.001" iyz="0" izz="0.001"/>
      </inertial>
      <visual name="visual_0_left_inner_knuckle">
        <origin xyz="0 0 0" rpy="0 0 0"/>
        <geometry>
          <mesh filename="meshes/stl/Robotiq Arg2F 140 Inner Knuckle.stl" scale="1.0 1.0 1.0"/>
        </geometry>
        <material name="LightGrey"/>
      </visual>
      <collision name="collision_0_left_inner_knuckle">
        <origin xyz="-5e-05 0.04992 -0.00069" rpy="-0.02655 0 0"/>
        <geometry>
          <box size="0.039 0.10207 0.01296"/>
        </geometry>
      </collision>
    </link>

    <link name="left_outer_finger">
      <inertial>
        <origin xyz="-0.00022 0.0409 -0.01413" rpy="0 0 0"/>
        <mass value="0.023"/>
        <inertia ixx="0.001" ixy="0" ixz="0" iyy="0.001" iyz="0" izz="0.001"/>
      </inertial>
      <visual name="visual_0_left_outer_finger">
        <origin xyz="0 0 0" rpy="0 0 0"/>
        <geometry>
          <mesh filename="meshes/stl/Robotiq Arg2F 140 Outer Finger.002.stl" scale="1.0 1.0 1.0"/>
        </geometry>
        <material name="LightGrey"/>
      </visual>
      <collision name="collision_0_left_outer_finger">
        <origin xyz="-0.00022 0.0409 -0.01413" rpy="0 0 0"/>
        <geometry>
          <box size="0.02705 0.09361 0.04008"/>
        </geometry>
      </collision>
    </link>

    <link name="left_outer_knuckle"><!--  -->
      <inertial>
        <origin xyz="0.0002 0.00614 0.0022" rpy="0 0 0"/>
        <mass value="0.009"/>
        <inertia ixx="0.001" ixy="0" ixz="0" iyy="0.001" iyz="0.00038" izz="0.00157"/>
      </inertial>
      <visual name="visual_0_left_outer_knuckle">
        <origin xyz="0 0 0" rpy="0 0 0"/>
        <geometry>
          <mesh filename="meshes/stl/Robotiq Arg2F 140 Outer Knuckle.002.stl" scale="1.0 1.0 1.0"/>
        </geometry>
        <material name="LightGrey"/>
      </visual>
      <collision name="collision_0_left_outer_knuckle">
        <origin xyz="0.0002 0.00614 0.0022" rpy="0.72482 -3.14159 0"/>
        <geometry>
          <box size="0.024 0.02193 0.0672"/>
        </geometry>
      </collision>
    </link>

    <link name="right_inner_finger"><!--  -->
      <inertial>
        <origin xyz="-0.0002 0.01926 -0.00896" rpy="0 0 0"/>
        <mass value="0.01"/>
        <inertia ixx="0.001" ixy="0" ixz="0" iyy="0.001" iyz="0" izz="0.001"/>
      </inertial>
      <visual name="visual_0_right_inner_finger">
        <origin xyz="0 0 0" rpy="0 0 0"/>
        <geometry>
          <mesh filename="meshes/stl/Robotiq Arg2F 140 Inner Finger.stl" scale="1.0 1.0 1.0"/>
        </geometry>
        <material name="LightGrey"/>
      </visual>
      <!-- <collision name="collision_0_right_inner_finger">               -->
      <!--   <origin xyz="-0.0002 0.01926 -0.00896" rpy="0 0 0"/>          -->
      <!--   <geometry>                                                    -->
      <!--     <box size="0.015 0.0505 0.02988"/>                          -->
      <!--   </geometry>                                                   -->
      <!-- </collision>                                                    -->
    </link>

	<link name="right_extension">

      <visual name="visual0_right_extension">
        <origin xyz="0 0.04 -0.027" rpy="1.57 0 0"/>
        <geometry>
          <box size="0.02 0.005 0.05"/>
        </geometry>
        <material name="LightGrey"/>
      </visual>

      <collision name="collision_0_right_extension">
        <origin xyz="0 0.04 -0.027" rpy="1.57 0 0"/>
        <geometry>
          <box size="0.02 0.005 0.05"/>
        </geometry>
      </collision>

  </link>

    <link name="right_inner_knuckle"><!--  -->
      <inertial>
        <origin xyz="-5e-05 0.04999 -0.00111" rpy="0 0 0"/>
        <mass value="0.027"/>
        <inertia ixx="0.001" ixy="0" ixz="0" iyy="0.001" iyz="0" izz="0.001"/>
      </inertial>
      <visual name="visual_0_right_inner_knuckle">
        <origin xyz="0 0 0" rpy="0 0 0"/>
        <geometry>
          <mesh filename="meshes/stl/Robotiq Arg2F 140 Inner Knuckle.002.stl" scale="1.0 1.0 1.0"/>
        </geometry>
        <material name="LightGrey"/>
      </visual>
      <collision name="collision_0_right_inner_knuckle">
        <origin xyz="-5e-05 0.04983 -0.00064" rpy="-0.02285 0 0"/>
        <geometry>
          <box size="0.039 0.10365 0.01316"/>
        </geometry>
      </collision>
    </link>

    <link name="right_outer_finger">
      <inertial>
        <origin xyz="-0.00022 0.0409 -0.01413" rpy="0 0 0"/>
        <mass value="0.023"/>
        <inertia ixx="0.001" ixy="0" ixz="0" iyy="0.001" iyz="-1e-05" izz="0.001"/>
      </inertial>
      <visual name="visual_0_right_outer_finger">
        <origin xyz="0 0 0" rpy="0 0 0"/>
        <geometry>
          <mesh filename="meshes/stl/Robotiq Arg2F 140 Outer Finger.stl" scale="1.0 1.0 1.0"/>
        </geometry>
        <material name="LightGrey"/>
      </visual>
      <collision name="collision_0_right_outer_finger">
        <origin xyz="-0.00022 0.0409 -0.01413" rpy="0 0 0"/>
        <geometry>
          <box size="0.02705 0.09361 0.04008"/>
        </geometry>
      </collision>
    </link>

    <link name="right_outer_knuckle"><!--  -->
      <inertial>
        <origin xyz="-0.0002 0.00614 0.0022" rpy="0 0 0"/>
        <mass value="0.009"/>
        <inertia ixx="0.001" ixy="0" ixz="0" iyy="0.001" iyz="-0.00038" izz="0.00157"/>
      </inertial>
      <visual name="visual_0_right_outer_knuckle">
        <origin xyz="0 0 0" rpy="0 0 0"/>
        <geometry>
          <mesh filename="meshes/stl/Robotiq Arg2F 140 Outer Knuckle.stl" scale="1.0 1.0 1.0"/>
        </geometry>
        <material name="LightGrey"/>
      </visual>
      <collision name="collision_0_right_outer_knuckle">
        <origin xyz="-0.0002 0.00614 0.0022" rpy="-0.72518 0 0"/>
        <geometry>
          <box size="0.024 0.02193 0.0672"/>
        </geometry>
      </collision>
    </link>

    <link name="robotiq_arg2f_base_link">
      <inertial>
        <origin xyz="0 0 0.02697" rpy="0 0 0"/>
        <mass value="0.227"/>
        <inertia ixx="0.001" ixy="0" ixz="0" iyy="0.001" iyz="0" izz="0.00103"/>
      </inertial>
      <visual name="visual_0_robotiq_arg2f_base_link">
        <origin xyz="0 0 0" rpy="0 0 0"/>
        <geometry>
          <mesh filename="meshes/stl/Robotiq Arg2F Base Link Fine.stl" scale="1.0 1.0 1.0"/>
        </geometry>
        <material name="LightGrey"/>
      </visual>
      <collision name="collision_0_base_link_cube">
        <origin xyz="0 0 0.06326" rpy="0 0 0"/>
        <geometry>
          <box size="0.02318 0.08722 0.05519"/>
        </geometry>
      </collision>
      <collision name="collision_0_base_link_cyl">
        <origin xyz="0 0 0.0175" rpy="0 0 0"/>
        <geometry>
          <cylinder radius="0.03778" length="0.035"/>
        </geometry>
      </collision>
    </link>

    <link name="grasp_location_indicator">
     <!-- <collision name="grasp_location_indicator_collision">   -->
     <!--   <origin xyz="0 0 0" rpy="0 0 0"/>           -->
     <!--   <geometry>                                  -->
     <!--     <box size="0.01 0.01 0.01"/>              -->
     <!--   </geometry>                                 -->
     <!-- </collision>                                  -->
     <visual name="grasp_location_indicator_visual">
        <origin xyz="0 0 0" rpy="0 0 0"/>
        <geometry>
          <sphere radius="0.005"/>
        </geometry>
        <material name="white_transparent"/>
     </visual>
    </link>

    <joint name="robotiq_arg2f_virtual_grasp_center_joint" type="fixed">
      <origin xyz="0 0 0.20" rpy="0 0 0"/>
      <parent link="robotiq_arg2f_base_link"/>
      <child link="grasp_location_indicator"/>
    </joint>

    <link name="robotiq_force_torque_frame_id">
    </link>

    <link name="shoulder_link"><!--  -->
      <inertial>
        <origin xyz="0 0 0" rpy="0 0 0"/>
        <mass value="3.7"/>
        <inertia ixx="0.01027" ixy="0" ixz="0" iyy="0.01027" iyz="0" izz="0.00666"/>
      </inertial>
      <visual name="visual_0_shoulder_link">
        <origin xyz="0 0 0" rpy="0 0 0"/>
        <geometry>
          <mesh filename="meshes/stl/Shoulder.009.stl" scale="1.0 1.0 1.0"/>
        </geometry>
        <material name="LightGrey"/>
      </visual>
      <collision name="collision_0_shoulder_link">
        <origin xyz="0 0.0055 0.00166" rpy="0 0 0"/>
        <geometry>
          <box size="0.119 0.13 0.13371"/>
        </geometry>
      </collision>
    </link>

    <link name="upper_arm_link"><!--  -->
      <inertial>
        <origin xyz="0 0 0" rpy="0 0 0"/>
        <mass value="8.393"/>
        <inertia ixx="0.22689" ixy="0" ixz="0" iyy="0.22689" iyz="0" izz="0.01511"/>
      </inertial>
      <visual name="visual_0_upper_arm_link">
        <origin xyz="0 0 0" rpy="0 0 0"/>
        <geometry>
          <mesh filename="meshes/stl/Upperarm.009.stl" scale="1.0 1.0 1.0"/>
        </geometry>
        <material name="LightGrey"/>
      </visual>
      <collision name="collision_0_upper_arm_link">
        <origin xyz="0 0.00166 0.2125" rpy="0 0 0"/>
        <geometry>
          <box size="0.119 0.13371 0.544"/>
        </geometry>
      </collision>
    </link>

    <link name="wrist_1_link"><!--  -->
      <inertial>
        <origin xyz="0 0 0" rpy="0 0 0"/>
        <mass value="1.219"/>
        <inertia ixx="0.11117" ixy="0" ixz="0" iyy="0.11117" iyz="0" izz="0.21942"/>
      </inertial>
      <visual name="visual_0_wrist_1_link">
        <origin xyz="0 0 0" rpy="0 0 0"/>
        <geometry>
          <mesh filename="meshes/stl/Wrist1.009.stl" scale="1.0 1.0 1.0"/>
        </geometry>
        <material name="LightGrey"/>
      </visual>
      <collision name="collision_0_wrist_1_link">
        <origin xyz="0 0.08993 -0.00485" rpy="0 0 0"/>
        <geometry>
          <box size="0.0775 0.08485 0.1047"/>
        </geometry>
      </collision>
    </link>

    <link name="wrist_2_link"><!--  -->
      <inertial>
        <origin xyz="0 0 0" rpy="0 0 0"/>
        <mass value="1.219"/>
        <inertia ixx="0.11117" ixy="0" ixz="0" iyy="0.11117" iyz="0" izz="0.21942"/>
      </inertial>
      <visual name="visual_0_wrist_2_link">
        <origin xyz="0 0 0" rpy="0 0 0"/>
        <geometry>
          <mesh filename="meshes/stl/Wrist2.009.stl" scale="1.0 1.0 1.0"/>
        </geometry>
        <material name="LightGrey"/>
      </visual>
      <collision name="collision_0_wrist_2_link">
        <origin xyz="0 -0.00485 0.09127" rpy="0 0 0"/>
        <geometry>
          <box size="0.0775 0.1047 0.08425"/>
        </geometry>
      </collision>
    </link>

    <link name="wrist_3_link"><!--  -->
      <inertial>
        <origin xyz="0 0 0" rpy="0 0 0"/>
        <mass value="0.1879"/>
        <inertia ixx="0.01714" ixy="0" ixz="0" iyy="0.01714" iyz="0" izz="0.03382"/>
      </inertial>
      <visual name="visual_0_wrist_3_link">
        <origin xyz="0 0 0" rpy="0 0 0"/>
        <geometry>
          <mesh filename="meshes/stl/Wrist3.009.stl" scale="1.0 1.0 1.0"/>
        </geometry>
        <material name="LightGrey"/>
      </visual>
      <collision name="collision_0_wrist_3_link">
        <origin xyz="0 0.06457 0.00275" rpy="0 0 0"/>
        <geometry>
          <box size="0.075 0.0345 0.0805"/>
        </geometry>
      </collision>
    </link>

    <link name="object">
    <!-- Sphere -->
      <visual>
        <geometry>
          <sphere radius="0.05"/>
        </geometry>
        <material>
          <color rgba="1 1 1 0"/>
        </material>
      </visual>
      <collision>
        <geometry>
          <sphere radius="0.05"/>
        </geometry>
      </collision>
    </link>
    <link name="goal">
      <visual name="visual_0_goal">
        <origin xyz="0 0 0" rpy="0 0 0"/>
        <geometry>
          <capsule radius="0.04" length="0.1"/>
        </geometry>
        <material name="red"/>
      </visual>
      <collision name="collision_0_goal">
        <origin xyz="0 0 0" rpy="0 0 0"/>
        <geometry>
          <capsule radius="0.04" length="0.1"/>
        </geometry>
      </collision>
    </link>

    <joint name="ee_fixed_joint" type="fixed">
      <origin xyz="0 0.0823 0" rpy="0 0 1.5708"/>
      <parent link="wrist_3_link"/>
      <child link="ee_link"/>
    </joint>

    <joint name="elbow_joint" type="revolute">
      <origin xyz="0 -0.1197 0.425" rpy="0 0 0"/>
      <parent link="upper_arm_link"/>
      <child link="forearm_link"/>
      <axis xyz="0 1.0 0"/>
      <limit lower="-6.28319" upper="6.28319" effort="150.0" velocity="3.15"/>
      <dynamics damping="0.001" friction="0.0"/>
    </joint>

    <joint name="finger_joint" type="revolute">
      <origin xyz="0 -0.0306 0.0549" rpy="2.2958 0 0"/>
      <parent link="robotiq_arg2f_base_link"/>
      <child link="left_outer_knuckle"/>
      <axis xyz="-1.0 0 0"/>
      <limit lower="0" upper="0.775" effort="1000" velocity="2.0"/>
    </joint>

    <joint name="fts_robotside_joint" type="fixed">
      <origin xyz="0 0 0" rpy="0 1.5708 0"/>
      <parent link="ee_link"/>
      <child link="fts_robotside"/>
    </joint>

    <joint name="left_inner_finger_joint" type="revolute">
      <origin xyz="0 0.08176 -0.02822" rpy="-0.725 0 0"/>
      <parent link="left_outer_finger"/>
      <child link="left_inner_finger"/>
      <axis xyz="1.0 0 0"/>
      <limit lower="0" upper="0.8757" effort="1000" velocity="2.0"/>
      <mimic joint="finger_joint" multiplier="1.0" offset="0.0"/>
    </joint>

    <joint name="left_inner_finger_joint_extension" type="fixed">
      <origin xyz="0 0 0" rpy="0 0 0"/>
      <parent link="left_inner_finger"/>
      <child link="left_extension"/>
      <axis xyz="1.0 0 0"/>
    </joint>

    <joint name="left_inner_knuckle_joint" type="revolute">
      <origin xyz="0 -0.0127 0.06142" rpy="2.2958 0 0"/>
      <parent link="robotiq_arg2f_base_link"/>
      <child link="left_inner_knuckle"/>
      <axis xyz="1.0 0 0"/>
      <limit lower="-0.8757" upper="0.8757" effort="1000.0" velocity="2.0"/>
      <mimic joint="finger_joint" multiplier="-1.0" offset="0.0"/>
    </joint>

    <joint name="left_outer_finger_joint" type="fixed">
      <origin xyz="0 0.01822 0.026" rpy="0 0 0"/>
      <parent link="left_outer_knuckle"/>
      <child link="left_outer_finger"/>
    </joint>

    <joint name="measurement_joint" type="fixed">
      <origin xyz="0 0 0.01625" rpy="0 0 0"/>
      <parent link="fts_robotside"/>
      <child link="robotiq_force_torque_frame_id"/>
    </joint>

    <joint name="right_inner_finger_joint" type="revolute">
      <origin xyz="0 0.08176 -0.02822" rpy="-0.725 0 0"/>
      <parent link="right_outer_finger"/>
      <child link="right_inner_finger"/>
      <axis xyz="1.0 0 0"/>
      <limit lower="-0.8757" upper="0.8757" effort="1000.0" velocity="2.0"/>
      <mimic joint="finger_joint" multiplier="1.0" offset="0.0"/>
    </joint>


    <joint name="right_inner_finger_joint_extension" type="fixed">
      <origin xyz="0 0 0" rpy="0 0 0"/>
      <parent link="right_inner_finger"/>
	    <child link="right_extension"/>
      <axis xyz="1.0 0 0"/>
    </joint>


    <joint name="right_inner_knuckle_joint" type="revolute">
      <origin xyz="0 0.0127 0.06142" rpy="-0.8458 -3.14159 0"/>
      <parent link="robotiq_arg2f_base_link"/>
      <child link="right_inner_knuckle"/>
      <axis xyz="1.0 0 0"/>
      <limit lower="-0.8757" upper="0.8757" effort="1000.0" velocity="2.0"/>
      <mimic joint="finger_joint" multiplier="-1.0" offset="0.0"/>
    </joint>

    <joint name="right_outer_finger_joint" type="fixed">
      <origin xyz="0 0.01822 0.026" rpy="0 0 0"/>
      <parent link="right_outer_knuckle"/>
      <child link="right_outer_finger"/>
    </joint>

    <joint name="right_outer_knuckle_joint" type="revolute">
      <origin xyz="0 0.0306 0.0549" rpy="-0.8458 3.14159 0"/>
      <parent link="robotiq_arg2f_base_link"/>
      <child link="right_outer_knuckle"/>
      <axis xyz="1.0 0 0"/>
      <limit lower="-0.775" upper="0.775" effort="1000.0" velocity="2.0"/>
      <mimic joint="finger_joint" multiplier="-1.0" offset="0.0"/>
    </joint>

    <joint name="robotiq_arg2f_base_joint" type="fixed">
      <origin xyz="0 0 0" rpy="0 0 0"/>
      <parent link="fts_toolside"/>
      <child link="robotiq_arg2f_base_link"/>
    </joint>

    <joint name="shoulder_lift_joint" type="revolute">
      <origin xyz="0 0.13585 0" rpy="0 1.5708 0"/>
      <parent link="shoulder_link"/>
      <child link="upper_arm_link"/>
      <axis xyz="0 1.0 0"/>
      <limit lower="-6.28319" upper="6.28319" effort="150.0" velocity="3.15"/>
      <dynamics damping="0.001" friction="0.0"/>
    </joint>

    <joint name="shoulder_pan_joint" type="revolute">
      <origin xyz="0 0 0.08916" rpy="0 0 0"/>
      <parent link="base_link"/>
      <child link="shoulder_link"/>
      <axis xyz="0 0 1.0"/>
      <limit lower="-6.28319" upper="6.28319" effort="150.0" velocity="3.15"/>
      <dynamics damping="0.001" friction="0.0"/>
    </joint>

    <joint name="toolside_joint" type="fixed">
      <origin xyz="0 0 0.0375" rpy="0 0 0"/>
      <parent link="fts_robotside"/>
      <child link="fts_toolside"/>
    </joint>

    <joint name="wrist_1_joint" type="revolute">
      <origin xyz="0 0 0.39225" rpy="0 1.5708 0"/>
      <parent link="forearm_link"/>
      <child link="wrist_1_link"/>
      <axis xyz="0 1.0 0"/>
      <limit lower="-6.28319" upper="6.28319" effort="28.0" velocity="3.2"/>
      <dynamics damping="0.001" friction="0.0"/>
    </joint>

    <joint name="wrist_2_joint" type="revolute">
      <origin xyz="0 0.093 0" rpy="0 0 0"/>
      <parent link="wrist_1_link"/>
      <child link="wrist_2_link"/>
      <axis xyz="0 0 1.0"/>
      <limit lower="-6.28319" upper="6.28319" effort="28.0" velocity="3.2"/>
      <dynamics damping="0.001" friction="0.0"/>
    </joint>

    <joint name="wrist_3_joint" type="revolute">
      <origin xyz="0 0 0.09465" rpy="0 0 0"/>
      <parent link="wrist_2_link"/>
      <child link="wrist_3_link"/>
      <axis xyz="0 1.0 0"/>
      <limit lower="-6.28319" upper="6.28319" effort="28.0" velocity="3.2"/>
      <dynamics damping="0.001" friction="0.0"/>
    </joint>

    <material name="black">
      <color rgba="0. 0. 0. 1.0"/>
    </material>

    <material name="LightGrey">
      <color rgba="0.7 0.7 0.7 1.0"/>
    </material>

    <material name="white_transparent">
      <color rgba="1. 1. 1. 0.5"/>
    </material>

  </robot>
